Workbook

Sheet Hướng dẫn
A1: GoAn — Bảng theo dõi dự án (Project Tracker)
A2: Đội 4 người · 8 giai đoạn · Cập nhật lần cuối 03/09/2026 · nhánh chore/p0-foundation, 5 commit, 129 test xanh
B5: CÁC SHEET
B6: Dashboard | C6: Tổng hợp tự động theo từng giai đoạn: số task, ngày công, % hoàn thành, số sprint còn lại. Không nhập tay ở đây.
B7: Hiện trạng | C7: Đánh giá từng phần của hệ thống hiện tại — căn cứ là mã nguồn đã đọc, không phải phỏng đoán.
B8: Backlog | C8: Bảng công việc chính. Đây là nơi DUY NHẤT cần cập nhật hằng ngày.
B9: Đội ngũ | C9: 4 vai trò, năng lực mỗi sprint, và tải công việc còn lại của từng người.
B10: Sprint | C10: Lịch 2 tuần/sprint, mục tiêu từng sprint.
B11: Rủi ro | C11: 9 rủi ro đã nhận diện, kèm cách giảm thiểu và người chịu trách nhiệm.
B12: Nhật ký | C12: 15 việc đã triển khai thật, kèm mã commit và bằng chứng kiểm chứng. Cả những chỗ đánh giá ban đầu sai và đã được sửa lại.
B13: Lists | C13: Danh sách giá trị cho ô chọn. Đừng xoá sheet này.
B15: CÁCH DÙNG HẰNG NGÀY
B16: 1 | C16: Mỗi ngày, cập nhật 2 cột trong sheet Backlog: 'Trạng thái' và '% hoàn thành'. Mọi thứ khác tự tính.
B17: 2 | C17: Điền cột 'Người làm' khi giao việc (đang để trống theo vai trò).
B18: 3 | C18: Điền cột 'Sprint' khi đưa task vào sprint.
B19: 4 | C19: Đầu mỗi sprint, xem sheet Đội ngũ để biết ai đang quá tải.
B21: QUY ƯỚC TRẠNG THÁI
B22: Đã xong | C22: Đạt đủ 'Định nghĩa hoàn thành' (cột E), đã merge, đã test. Không có 'gần xong'.
B23: Đang làm | C23: Có người đang làm. Một người không nên có quá 2 task Đang làm cùng lúc.
B24: Chưa bắt đầu | C24: Đã sẵn sàng để nhận.
B25: Bị chặn | C25: Không làm tiếp được vì lý do bên ngoài. PHẢI ghi lý do ở cột Ghi chú và đưa ra họp hằng ngày.
B27: QUY ƯỚC ƯU TIÊN
B28: P0-Bắt buộc | C28: Không có thì giai đoạn không đóng được.
B29: P1-Cao | C29: Cần cho vận hành thật, có thể lùi 1 sprint.
B30: P2-Trung bình | C30: Cải thiện chất lượng, lùi được.
B31: P3-Thấp | C31: Làm khi còn thời gian.
B33: ĐƯA LÊN GOOGLE SHEETS
B34: Cách 1 | C34: Google Drive → Mới → Tải tệp lên → chọn file .xlsx này → mở bằng Google Sheets. Toàn bộ công thức, định dạng và ô chọn được giữ nguyên.
B35: Cách 2 | C35: Trong Google Sheets: Tệp → Nhập → Tải lên → 'Thay thế bảng tính'.
B36: Lưu ý | C36: Sau khi lên Sheets, nên bật: Dữ liệu → Bộ lọc trên sheet Backlog, và chia sẻ quyền Chỉnh sửa cho cả đội.
B38: ĐIỀU CẦN BIẾT TRƯỚC KHI ĐỌC SỐ
B39: Ước tính | C39: Đơn vị là NGÀY CÔNG (person-day) của một người làm việc tập trung, chưa gồm họp và hỗ trợ.
B40: Năng lực | C40: Sprint = 2 tuần = 10 ngày làm việc, nhưng chỉ tính 8 ngày hiệu quả/người (trừ họp, review, sự cố).
B41: Task đã xong | C41: Những dòng ghi '[ĐÃ CÓ]' là phần code đã tồn tại và đã được kiểm chứng — để 0 ngày công, chỉ dùng để phản ánh đúng % hoàn thành.
B42: Điểm nghẽn | C42: Với 4 người, đường găng là app mobile. Xem sheet Rủi ro, mục R1 — đây là điều cần quyết sớm nhất.

Sheet Dashboard
A1: DASHBOARD — Tình trạng theo từng giai đoạn
A2: Toàn bộ số liệu tự tính từ sheet Backlog và sheet Đội ngũ. Các giả định tính toán nằm ở cuối sheet này.
A4: Giai đoạn | B4: Tổng task | C4: Đã xong | D4: Đang làm | E4: Chưa bắt đầu | F4: Bị chặn | G4: Tổng ngày công | H4: Ngày công còn lại | I4: % hoàn thành | J4: Số sprint cần (4 người) | K4: Trạng thái tổng
A5: P0 - Dọn nền | B5: =COUNTIFS(Backlog!$B$5:$B$135,$A5) | C5: =COUNTIFS(Backlog!$B$5:$B$135,$A5,Backlog!$K$5:$K$135,"Đã xong") | D5: =COUNTIFS(Backlog!$B$5:$B$135,$A5,Backlog!$K$5:$K$135,"Đang làm") | E5: =COUNTIFS(Backlog!$B$5:$B$135,$A5,Backlog!$K$5:$K$135,"Chưa bắt đầu") | F5: =COUNTIFS(Backlog!$B$5:$B$135,$A5,Backlog!$K$5:$K$135,"Bị chặn") | G5: =SUMIFS(Backlog!$H$5:$H$135,Backlog!$B$5:$B$135,$A5) | H5: =SUMIFS(Backlog!$M$5:$M$135,Backlog!$B$5:$B$135,$A5) | I5: =IFERROR(1-H5/G5,1) | J5: =IFERROR(ROUND(H5/$B$16,1),0) | K5: =IF(F5>0,"Có việc bị chặn",IF(I5>=1,"Hoàn thành",IF(D5>0,"Đang chạy","Chưa bắt đầu")))
A6: P1 - IAM & Console khung | B6: =COUNTIFS(Backlog!$B$5:$B$135,$A6) | C6: =COUNTIFS(Backlog!$B$5:$B$135,$A6,Backlog!$K$5:$K$135,"Đã xong") | D6: =COUNTIFS(Backlog!$B$5:$B$135,$A6,Backlog!$K$5:$K$135,"Đang làm") | E6: =COUNTIFS(Backlog!$B$5:$B$135,$A6,Backlog!$K$5:$K$135,"Chưa bắt đầu") | F6: =COUNTIFS(Backlog!$B$5:$B$135,$A6,Backlog!$K$5:$K$135,"Bị chặn") | G6: =SUMIFS(Backlog!$H$5:$H$135,Backlog!$B$5:$B$135,$A6) | H6: =SUMIFS(Backlog!$M$5:$M$135,Backlog!$B$5:$B$135,$A6) | I6: =IFERROR(1-H6/G6,1) | J6: =IFERROR(ROUND(H6/$B$16,1),0) | K6: =IF(F6>0,"Có việc bị chặn",IF(I6>=1,"Hoàn thành",IF(D6>0,"Đang chạy","Chưa bắt đầu")))
A7: P2 - Chat & Support | B7: =COUNTIFS(Backlog!$B$5:$B$135,$A7) | C7: =COUNTIFS(Backlog!$B$5:$B$135,$A7,Backlog!$K$5:$K$135,"Đã xong") | D7: =COUNTIFS(Backlog!$B$5:$B$135,$A7,Backlog!$K$5:$K$135,"Đang làm") | E7: =COUNTIFS(Backlog!$B$5:$B$135,$A7,Backlog!$K$5:$K$135,"Chưa bắt đầu") | F7: =COUNTIFS(Backlog!$B$5:$B$135,$A7,Backlog!$K$5:$K$135,"Bị chặn") | G7: =SUMIFS(Backlog!$H$5:$H$135,Backlog!$B$5:$B$135,$A7) | H7: =SUMIFS(Backlog!$M$5:$M$135,Backlog!$B$5:$B$135,$A7) | I7: =IFERROR(1-H7/G7,1) | J7: =IFERROR(ROUND(H7/$B$16,1),0) | K7: =IF(F7>0,"Có việc bị chặn",IF(I7>=1,"Hoàn thành",IF(D7>0,"Đang chạy","Chưa bắt đầu")))
A8: P3 - Driver App | B8: =COUNTIFS(Backlog!$B$5:$B$135,$A8) | C8: =COUNTIFS(Backlog!$B$5:$B$135,$A8,Backlog!$K$5:$K$135,"Đã xong") | D8: =COUNTIFS(Backlog!$B$5:$B$135,$A8,Backlog!$K$5:$K$135,"Đang làm") | E8: =COUNTIFS(Backlog!$B$5:$B$135,$A8,Backlog!$K$5:$K$135,"Chưa bắt đầu") | F8: =COUNTIFS(Backlog!$B$5:$B$135,$A8,Backlog!$K$5:$K$135,"Bị chặn") | G8: =SUMIFS(Backlog!$H$5:$H$135,Backlog!$B$5:$B$135,$A8) | H8: =SUMIFS(Backlog!$M$5:$M$135,Backlog!$B$5:$B$135,$A8) | I8: =IFERROR(1-H8/G8,1) | J8: =IFERROR(ROUND(H8/$B$16,1),0) | K8: =IF(F8>0,"Có việc bị chặn",IF(I8>=1,"Hoàn thành",IF(D8>0,"Đang chạy","Chưa bắt đầu")))
A9: P4 - Rider App | B9: =COUNTIFS(Backlog!$B$5:$B$135,$A9) | C9: =COUNTIFS(Backlog!$B$5:$B$135,$A9,Backlog!$K$5:$K$135,"Đã xong") | D9: =COUNTIFS(Backlog!$B$5:$B$135,$A9,Backlog!$K$5:$K$135,"Đang làm") | E9: =COUNTIFS(Backlog!$B$5:$B$135,$A9,Backlog!$K$5:$K$135,"Chưa bắt đầu") | F9: =COUNTIFS(Backlog!$B$5:$B$135,$A9,Backlog!$K$5:$K$135,"Bị chặn") | G9: =SUMIFS(Backlog!$H$5:$H$135,Backlog!$B$5:$B$135,$A9) | H9: =SUMIFS(Backlog!$M$5:$M$135,Backlog!$B$5:$B$135,$A9) | I9: =IFERROR(1-H9/G9,1) | J9: =IFERROR(ROUND(H9/$B$16,1),0) | K9: =IF(F9>0,"Có việc bị chặn",IF(I9>=1,"Hoàn thành",IF(D9>0,"Đang chạy","Chưa bắt đầu")))
A10: P5 - Ledger & Finance | B10: =COUNTIFS(Backlog!$B$5:$B$135,$A10) | C10: =COUNTIFS(Backlog!$B$5:$B$135,$A10,Backlog!$K$5:$K$135,"Đã xong") | D10: =COUNTIFS(Backlog!$B$5:$B$135,$A10,Backlog!$K$5:$K$135,"Đang làm") | E10: =COUNTIFS(Backlog!$B$5:$B$135,$A10,Backlog!$K$5:$K$135,"Chưa bắt đầu") | F10: =COUNTIFS(Backlog!$B$5:$B$135,$A10,Backlog!$K$5:$K$135,"Bị chặn") | G10: =SUMIFS(Backlog!$H$5:$H$135,Backlog!$B$5:$B$135,$A10) | H10: =SUMIFS(Backlog!$M$5:$M$135,Backlog!$B$5:$B$135,$A10) | I10: =IFERROR(1-H10/G10,1) | J10: =IFERROR(ROUND(H10/$B$16,1),0) | K10: =IF(F10>0,"Có việc bị chặn",IF(I10>=1,"Hoàn thành",IF(D10>0,"Đang chạy","Chưa bắt đầu")))
A11: P6 - Partner & Website | B11: =COUNTIFS(Backlog!$B$5:$B$135,$A11) | C11: =COUNTIFS(Backlog!$B$5:$B$135,$A11,Backlog!$K$5:$K$135,"Đã xong") | D11: =COUNTIFS(Backlog!$B$5:$B$135,$A11,Backlog!$K$5:$K$135,"Đang làm") | E11: =COUNTIFS(Backlog!$B$5:$B$135,$A11,Backlog!$K$5:$K$135,"Chưa bắt đầu") | F11: =COUNTIFS(Backlog!$B$5:$B$135,$A11,Backlog!$K$5:$K$135,"Bị chặn") | G11: =SUMIFS(Backlog!$H$5:$H$135,Backlog!$B$5:$B$135,$A11) | H11: =SUMIFS(Backlog!$M$5:$M$135,Backlog!$B$5:$B$135,$A11) | I11: =IFERROR(1-H11/G11,1) | J11: =IFERROR(ROUND(H11/$B$16,1),0) | K11: =IF(F11>0,"Có việc bị chặn",IF(I11>=1,"Hoàn thành",IF(D11>0,"Đang chạy","Chưa bắt đầu")))
A12: P7 - Hardening | B12: =COUNTIFS(Backlog!$B$5:$B$135,$A12) | C12: =COUNTIFS(Backlog!$B$5:$B$135,$A12,Backlog!$K$5:$K$135,"Đã xong") | D12: =COUNTIFS(Backlog!$B$5:$B$135,$A12,Backlog!$K$5:$K$135,"Đang làm") | E12: =COUNTIFS(Backlog!$B$5:$B$135,$A12,Backlog!$K$5:$K$135,"Chưa bắt đầu") | F12: =COUNTIFS(Backlog!$B$5:$B$135,$A12,Backlog!$K$5:$K$135,"Bị chặn") | G12: =SUMIFS(Backlog!$H$5:$H$135,Backlog!$B$5:$B$135,$A12) | H12: =SUMIFS(Backlog!$M$5:$M$135,Backlog!$B$5:$B$135,$A12) | I12: =IFERROR(1-H12/G12,1) | J12: =IFERROR(ROUND(H12/$B$16,1),0) | K12: =IF(F12>0,"Có việc bị chặn",IF(I12>=1,"Hoàn thành",IF(D12>0,"Đang chạy","Chưa bắt đầu")))
A13: TỔNG DỰ ÁN | B13: =SUM(B5:B12) | C13: =SUM(C5:C12) | D13: =SUM(D5:D12) | E13: =SUM(E5:E12) | F13: =SUM(F5:F12) | G13: =SUM(G5:G12) | H13: =SUM(H5:H12) | I13: =IFERROR(1-H13/G13,0) | J13: =IFERROR(ROUND(H13/$B$16,1),0)
A15: GIẢ ĐỊNH TÍNH TOÁN
A16: Năng lực đội mỗi sprint (ngày công) | B16: ='Đội ngũ'!F9 | C16: Tự lấy từ sheet Đội ngũ (tổng cột Năng lực thực). Sửa hệ số sẵn sàng ở sheet đó, số này tự đổi.
A17: Độ dài sprint (tuần) | B17: 2 | C17: Chuẩn Scrum 2 tuần
A18: Số người trong đội | B18: 4 | C18: TL, BE, MOB, FE(+QA) — theo lựa chọn đội nhỏ 3-4 người
A20: Ước tính thời gian còn lại (sprint) | B20: =ROUND(H13/B16,1) | C20: Ngày công còn lại chia cho năng lực mỗi sprint. Con số lý thuyết — chưa tính phụ thuộc tuần tự giữa các giai đoạn và điểm nghẽn mobile (xem sheet Rủi ro R1).
A21: Ước tính thời gian còn lại (tuần) | B21: =ROUND(B20*B17,0)

Sheet Hiện trạng
A1: HIỆN TRẠNG — Đánh giá thực tế từng phần hệ thống
A2: Căn cứ: rà soát toàn bộ mã nguồn ~7.500 dòng trong repo Goan ngày 03/09/2026, đã chạy thật bộ test (51/51 pass). Không phải ước lượng cảm tính.
A4: Thành phần hệ thống | B4: Đánh giá | C4: Mức hoàn thiện | D4: Căn cứ (đã đọc mã nguồn) | E4: Việc còn lại nằm ở đâu
A5: Backend - Pricing engine | B5: Đã xong | C5: 1 | D5: 148 dòng service + 170 dòng test, đúng biểu giá deck (3 khung giờ, phụ thu đón xa 20k) | E5: Không cần làm lại
A6: Backend - Trip state machine | B6: Đã xong | C6: 1 | D6: Bảng transition rõ ràng, chặn cứng in_progress chỉ từ qr_verified | E6: Nền tảng chống đơn ma đã chắc
A7: Backend - Vòng đời chuyến | B7: Đã xong | C7: 1 | D7: Chốt cước + escrow + payment trong 1 transaction; thêm trip_events, mốc /arrived, /rate, điều phối thủ công /ops/trips/{id}/assign-driver | E7: Không còn lỗ hổng ở P0
A8: Backend - Matching | B8: Gần xong | C8: 0.95 | D8: Redis GEO, nới bán kính 5/8/12km, khoá SETNX chống race, gán thủ công từ ops đã có | E8: Thiếu: trợ cấp vùng mới (đã có khung)
A9: Backend - Escrow (ký quỹ) | B9: Đã xong | C9: 0.95 | D9: Trích 15% payout, không vượt định mức, phạt cho phép âm, hoàn quỹ 45 ngày | E9: Thiếu: duyệt maker-checker khi hoàn quỹ
A10: Backend - Anti-fraud | B10: Đã xong | C10: 0.95 | D10: Đủ 4 cơ chế: đơn ma, chạy vòng (cap 1.5x + phạt x2), thanh toán ngoài app, tráo tài xế | E10: Thiếu: màn hình xử lý cho Risk analyst
A11: Backend - Payments | B11: Một nửa | C11: 0.45 | D11: Có ví pending/available, rút tiền, đối soát ngày. Nhưng gateway là mock, không double-entry, không payout theo kỳ | E11: P5 xử lý
A12: Backend - Partners | B12: Một nửa | C12: 0.55 | D12: Model + QR + hoa hồng + hoá đơn (mock) | E12: Thiếu: đăng nhập đối tác, portal
A13: Backend - WebSocket | B13: Một nửa | C13: 0.5 | D13: connection_manager + Redis pub/sub + events cơ bản | E13: Cần mở rộng đa topic cho chat và ops
A14: Backend - Auth | B14: Gần xong | C14: 0.85 | D14: OTP + JWT; access token 15 phút, xoay vòng refresh token + thu hồi cả phiên khi dùng lại token cũ, hạn mức OTP theo số điện thoại | E14: Thiếu: 2FA nội bộ cho nhân sự (P1)
A15: Backend - Chat | B15: Chưa có | C15: 0 | D15: Không tồn tại trong code | E15: Toàn bộ P2
A16: Backend - Support/Ticket | B16: Chưa có | C16: 0 | D16: Không tồn tại trong code | E16: Toàn bộ P2
... A26: Tài liệu thiết kế | B26: Đã xong | C26: 1 | D26: 4 tài liệu: kiến trúc, luồng thanh toán, phân định hệ thống, CLAUDE.md | E26: Cập nhật khi có quyết định mới

Sheet Backlog
A1: BACKLOG — Danh sách công việc
A2: Chỉ cần cập nhật cột K (Trạng thái) và L (% hoàn thành). Cột M tự tính. Cột O ghi căn cứ đánh giá hiện trạng.
A4: ID | B4: Giai đoạn | C4: Nhóm | D4: Công việc | E4: Định nghĩa hoàn thành (DoD) | F4: Vai trò | G4: Người làm | H4: Ước tính (ngày) | I4: Ưu tiên | J4: Phụ thuộc | K4: Trạng thái | L4: % hoàn thành | M4: Ngày công còn lại | N4: Sprint | O4: Căn cứ đánh giá / Ghi chú
A5: P0-01 | B5: P0 - Dọn nền | C5: Repo | D5: Quyết định & xoá goan-backend (bản nháp cũ) | E5: Repo chỉ còn 1 backend; README ghi rõ lý do | F5: TL | H5: 1 | I5: P0-Bắt buộc | K5: Đang làm | L5: 0.7 | M5: =H5*(1-L5) | O5: 03/09: đã chuyển thành services/_deprecated-api-v0 kèm DEPRECATED.md. Điều kiện xoá ĐÃ ĐẠT (P4-12 xong, app khách không còn phụ thuộc). Chỉ còn thao tác xoá thư mục.
A6: P0-02 | B6: P0 - Dọn nền | C6: Repo | D6: Dựng monorepo pnpm workspace + Turborepo | E6: pnpm i chạy được ở root; turbo build/lint/test xanh | F6: TL | H6: 3 | I6: P0-Bắt buộc | K6: Đã xong | L6: 1 | M6: =H6*(1-L6) | O6: 03/09 XONG: pnpm-workspace.yaml + turbo.json + .editorconfig + README. pnpm install xanh (244 gói), pnpm-lock.yaml đã commit, pnpm build xanh
A7: P0-03 | B7: P0 - Dọn nền | C7: Repo | D7: Di chuyển goan-backend-spec → services/api | E7: CI xanh sau khi đổi đường dẫn; import không gãy | F7: BE | H7: 1 | I7: P0-Bắt buộc | J7: Dựng monorepo | K7: Đã xong | L7: 1 | M7: =H7*(1-L7) | O7: 03/09 XONG: 181 file đổi đường dẫn, 51/51 test vẫn xanh. goan-customer-app → apps/customer-web (@goan/customer-web)
A8: P0-04 | B8: P0 - Dọn nền | C8: Repo | D8: Gom 4 file .md vào docs/ | E8: docs/ có đủ 4 tài liệu, README root trỏ tới | F8: TL | H8: 0.5 | I8: P2-Trung bình | J8: Dựng monorepo | K8: Đã xong | L8: 1 | M8: =H8*(1-L8) | O8: 03/09 XONG: docs/ có 3 tài liệu + file tracker này. README root có bảng dẫn đường
A9: P0-05 | B9: P0 - Dọn nền | C9: Backend | D9: Chuẩn hoá lint/type: ruff + mypy strict cho services/api | E9: 0 lỗi ruff, mypy pass ở mức strict cho domains/ | F9: BE | H9: 2 | I9: P1-Cao | K9: Đã xong | L9: 1 | M9: =H9*(1-L9) | O9: 03/09 XONG: ruff (E,F,I,UP,B,C4,SIM,ASYNC) sạch sau khi sửa 92 lỗi; ruff format toàn bộ; mypy SẠCH 78 file. Sửa được 3 bug tiềm ẩn thật — xem sheet Nhật ký
A10: P0-06 | B10: P0 - Dọn nền | C10: Backend | D10: Sinh OpenAPI → packages/api-client (TypeScript SDK) | E10: Chạy 1 lệnh sinh lại SDK; CI đỏ nếu SDK lệch backend | F10: BE | H10: 3 | I10: P0-Bắt buộc | J10: Di chuyển services/api | K10: Đã xong | L10: 1 | M10: =H10*(1-L10) | O10: 03/09 XONG: export_openapi.py xuất 33 đường dẫn / 54 schema; openapi-typescript sinh schema.d.ts 2.168 dòng; @goan/api-client typecheck sạch; CI có job so sánh chống lệch
A11: P0-07 | B11: P0 - Dọn nền | C11: DevOps | D11: GitHub Actions: lint + typecheck + pytest + build | E11: PR không merge được khi CI đỏ | F11: TL | H11: 3 | I11: P0-Bắt buộc | J11: Dựng monorepo | K11: Đang làm | L11: 0.85 | M11: =H11*(1-L11) | O11: 03/09: .github/workflows/ci.yml 4 job (backend, migration-check, api-contract, frontend) đều xanh. Còn: bật branch protection trên GitHub để PR đỏ không merge được — thao tác trên giao diện.
A12: P0-08 | B12: P0 - Dọn nền | C12: DevOps | D12: CI kiểm tra model vs migration (alembic check) | E12: Sửa model mà quên migration → CI đỏ | F12: BE | H12: 2 | I12: P1-Cao | J12: GitHub Actions | K12: Đã xong | L12: 1 | M12: =H12*(1-L12) | O12: 03/09 XONG: job migration-check chạy alembic upgrade head + alembic check trên container postgis:16-3.4. Sửa model mà quên migration là CI đỏ ngay.
A13: P0-09 | B13: P0 - Dọn nền | C13: DevOps | D13: Docker Compose dev đầy đủ (api, postgres+postgis, redis, celery worker/beat) | E13: docker compose up chạy được toàn bộ stack | F13: TL | H13: 2 | I13: P1-Cao | K13: Đang làm | L13: 0.9 | M13: =H13*(1-L13) | O13: 03/09: compose đủ 4 dịch vụ (postgres+postgis, redis, app, worker chạy kèm beat -B); docker compose config hợp lệ. Còn: chạy up kiểm chứng trên máy có Docker.
A14: P0-10 | B14: P0 - Dọn nền | C14: DevOps | D14: Dựng môi trường staging (VPS + domain + TLS) | E14: Deploy tự động từ nhánh main lên staging | F14: TL | H14: 5 | I14: P0-Bắt buộc | J14: GitHub Actions | K14: Chưa bắt đầu | L14: 0 | M14: =H14*(1-L14)
A15: P0-11 | B15: P0 - Dọn nền | C15: DevOps | D15: Quản lý secret (SOPS hoặc Doppler), gỡ secret khỏi .env trong repo | E15: Không còn secret nào trong git; khoá tách theo môi trường | F15: TL | H15: 2 | I15: P0-Bắt buộc | K15: Chưa bắt đầu | L15: 0 | M15: =H15*(1-L15) | O15: Hiện .env đang bị gitignore đúng, nhưng chưa có cơ chế quản lý khoá production
A16: P0-12 | B16: P0 - Dọn nền | C16: Backend | D16: Nâng cấp rate limit: cửa sổ trượt + hạn mức riêng theo endpoint | E16: Không lách được ở ranh giới phút; OTP có hạn mức riêng | F16: BE | H16: 3 | I16: P0-Bắt buộc | K16: Đã xong | L16: 1 | M16: =H16*(1-L16) | O16: SỬA ĐÁNH GIÁ TRƯỚC: rate limit vốn ĐÃ dùng Redis, không phải in-process — đánh giá ban đầu sai. Vấn đề thật là cửa sổ cố định theo phút cho gửi gấp đôi hạn mức quanh ranh giới. 03/09 XONG: đổi sang ZSET cửa sổ trượt, thêm hạn mức riêng request-otp 5/5phút, verify-otp 10/5phút, tạo chuyến 20/phút, kèm header X-RateLimit-*
A17: P0-13 | B17: P0 - Dọn nền | C17: Backend | D17: Middleware Idempotency-Key dùng chung cho mọi POST chạm tiền | E17: Gửi trùng request không tạo 2 bản ghi; lưu Redis 24h | F17: BE | H17: 3 | I17: P0-Bắt buộc | K17: Đã xong | L17: 1 | M17: =H17*(1-L17) | O17: 03/09 XONG: core/idempotency.py bảo vệ 5 nhóm endpoint (tạo chuyến, complete, cancel, withdraw, accept). Gửi trùng phát lại response cũ; bản gốc đang chạy trả 409. Chỉ cache kết quả thành công. 16 test QA-IDM
A18: P0-14 | B18: P0 - Dọn nền | C18: Backend | D18: Xoay vòng refresh token + danh sách thu hồi | E18: Dùng lại refresh cũ → thu hồi cả họ token | F18: BE | H18: 4 | I18: P0-Bắt buộc | K18: Đã xong | L18: 1 | M18: =H18*(1-L18) | O18: 03/09 XONG: theo OAuth 2.0 BCP §4.13. Mỗi lần đăng nhập = 1 họ token; dùng lại token đã tiêu thì thu hồi cả họ. Token cũ chưa có fam được nâng cấp 1 lần nên deploy không đá hết người dùng. Thêm POST /auth/logout. 9 test QA-AUTH
A19: P0-15 | B19: P0 - Dọn nền | C19: Backend | D19: Rút access token 60 phút → 15 phút, client tự refresh | E19: App không bị đăng xuất đột ngột khi token hết hạn | F19: BE | H19: 1 | I19: P0-Bắt buộc | J19: Xoay vòng refresh token | K19: Đã xong | L19: 1 | M19: =H19*(1-L19) | O19: 03/09 XONG phía backend (ACCESS_TOKEN_EXPIRE_MINUTES = 15). LƯU Ý: apps/customer-web hiện gặp 401 là đăng xuất luôn — phải làm auto-refresh cùng lúc chuyển sang @goan/api-client (P4-12)
A20: P0-16 | B20: P0 - Dọn nền | C20: DevOps | D20: Sentry + OpenTelemetry trace + Prometheus metrics | E20: Xem được trace 1 request xuyên suốt; alert lỗi về Slack | F20: TL | H20: 4 | I20: P1-Cao | J20: Dựng staging | K20: Đã xong | L20: 1 | M20: =H20*(1-L20) | O20: 03/09 XONG: Prometheus /metrics (nhãn theo template route, khoá bằng METRICS_TOKEN), OTel trace tuỳ chọn, Sentry theo DSN, X-Request-ID xuyên log/audit. Alert Slack nối khi có staging.
A21: P0-17 | B21: P0 - Dọn nền | C21: Backend | D21: Tách /health (liveness) và /ready (readiness có DB+Redis) | E21: K8s/LB dùng đúng probe | F21: BE | H21: 1 | I21: P2-Trung bình | K21: Đã xong | L21: 1 | M21: =H21*(1-L21) | O21: 03/09 XONG: /health không chạm DB (tránh restart container vô ích khi DB sự cố); /ready kiểm DB+Redis và trả 503 khi chưa sẵn sàng
A22: P0-18 | B22: P0 - Dọn nền | C22: DevOps | D22: Backup PostgreSQL daily + PITR | E22: Khôi phục thử thành công về 1 thời điểm bất kỳ | F22: TL | H22: 3 | I22: P0-Bắt buộc | J22: Dựng staging | K22: Chưa bắt đầu | L22: 0 | M22: =H22*(1-L22) | O22: Bắt buộc vì có dữ liệu ký quỹ của tài xế
A23: P0-19 | B23: P0 - Dọn nền | C23: Backend | D23: Bảng audit_logs + middleware ghi mọi thao tác ghi | E23: Mọi POST/PATCH/DELETE để lại: ai, IP, payload trước/sau | F23: BE | H23: 3 | I23: P0-Bắt buộc | K23: Đã xong | L23: 1 | M23: =H23*(1-L23) | O23: 03/09 XONG: migration 0002 + domains/audit + middleware. Che đệ quy 17 trường nhạy cảm, suy ra resource_type/resource_id từ đường dẫn. Lỗi ghi audit không làm hỏng request. 19 test QA-AUD
A24: P0-20 | B24: P0 - Dọn nền | C24: QA | D24: Dựng vai trò QA: quyền hạn, quy trình, Definition of Done | E24: Có tài liệu đội đọc là làm theo được, không cần hỏi lại | F24: FE | H24: 2 | I24: P0-Bắt buộc | K24: Đã xong | L24: 1 | M24: =H24*(1-L24) | O24: 03/09 XONG: docs/QA/QA_ROLE.md — quyền chặn merge/release, DoD 9 điểm, phân loại lỗi 5 mức kèm ví dụ GoAn, 6 vùng rủi ro xếp theo thiệt hại
A25: P0-21 | B25: P0 - Dọn nền | C25: QA | D25: Chiến lược kiểm thử + hệ thống marker | E25: Chạy được từng nhóm test riêng; marker sai thì đỏ | F25: FE | H25: 2 | I25: P0-Bắt buộc | K25: Đã xong | L25: 1 | M25: =H25*(1-L25) | O25: 03/09 XONG: docs/QA/TEST_STRATEGY.md + 6 marker (unit/integration/api/security/money/prd) với --strict-markers. Ghi rõ cả những gì test tự động KHÔNG bắt được
A26: P0-22 | B26: P0 - Dọn nền | C26: QA | D26: Ma trận truy vết PRD → test case | E26: Mỗi yêu cầu PRD chỉ ra được test nào chứng minh nó đúng | F26: FE | H26: 3 | I26: P0-Bắt buộc | J26: Chiến lược kiểm thử | K26: Đã xong | L26: 1 | M26: =H26*(1-L26) | O26: 03/09 XONG: docs/QA/TRACEABILITY.md — 58 yêu cầu trích từ 3 tài liệu, 38 đã có test (66%), 2 còn thiếu có kế hoạch cụ thể, 18 thuộc P1/P2/P5
A27: P0-23 | B27: P0 - Dọn nền | C27: QA | D27: Mẫu báo lỗi + PR template bắt buộc | E27: Báo lỗi có đủ bước tái hiện và request_id; MR phải trả lời 'test này đỏ khi nào' | F27: FE | H27: 1 | I27: P1-Cao | K27: Đã xong | L27: 1 | M27: =H27*(1-L27) | O27: 03/09 XONG: docs/QA/BUG_TEMPLATE.md + .github/pull_request_template.md. Sau mỗi sự cố bắt buộc viết test tái hiện TRƯỚC khi sửa
A28: P0-24 | B28: P0 - Dọn nền | C28: QA | D28: Hạ tầng test: Redis giả, client API qua middleware thật, ngưỡng độ phủ | E28: Test được cả tầng middleware và các nhánh fail-open | F28: FE | H28: 3 | I28: P0-Bắt buộc | K28: Đã xong | L28: 1 | M28: =H28*(1-L28) | O28: 03/09 XONG: tests/fakes.py (Redis giả có GEO + sorted set + cờ mô phỏng Redis chết), fixture api_client chạy qua đúng chuỗi middleware thật, CI có ngưỡng độ phủ 75% và job riêng cho nhóm money/security
A29: P0-25 | B29: P0 - Dọn nền | C29: QA | D29: Trả nợ kiểm thử: matching và mã hoá CCCD | E29: 4 yêu cầu PRD có code nhưng chưa ai chứng minh đúng | F29: FE | H29: 2 | I29: P1-Cao | J29: Hạ tầng test | K29: Đã xong | L29: 1 | M29: =H29*(1-L29) | O29: 03/09 XONG: PRD-MATCH-01/02/03 (bán kính có nới thật, 2 tài xế cùng nhận chỉ 1 người thắng, chuyến quá hạn thoát trạng thái chờ) + PRD-SEC-05 (mã hoá CCCD). Tổng 51 → 129 test, độ phủ 78% → 81%
A30: P0-26 | B30: P0 - Dọn nền | C30: Backend | D30: [ĐÃ CÓ] Migration khởi tạo 18 bảng lõi | E30: alembic upgrade head chạy sạch | F30: BE | H30: 0 | I30: P0-Bắt buộc | K30: Đã xong | L30: 1 | M30: =H30*(1-L30) | O30: Đã kiểm chứng: alembic/versions/0001_initial_schema.py, 18 create_table
A31: P0-27 | B31: P0 - Dọn nền | C31: Backend | D31: [ĐÃ CÓ] Bộ test tự động 51 test (pricing, escrow, fraud, payments, state machine, luồng chuyến) | E31: pytest -q xanh, không cần Postgres/Redis | F31: BE | H31: 0 | I31: P0-Bắt buộc | K31: Đã xong | L31: 1 | M31: =H31*(1-L31) | O31: Đã kiểm chứng: chạy thật, 51 passed in 2.52s
A32: P0-28 | B32: P0 - Dọn nền | C32: Backend | D32: [ĐÃ CÓ] JSON structured logging + log_event | E32: Log ra JSON, có event name | F32: BE | H32: 0 | I32: P1-Cao | K32: Đã xong | L32: 1 | M32: =H32*(1-L32) | O32: core/logging.py
A33: P1-01 | B33: P1 - IAM & Console khung | C33: Backend | D33: domains/iam: staff_users, roles, permissions, role_permissions | E33: Migration + seed 12 vai trò theo tài liệu phân định | F33: BE | H33: 3 | I33: P0-Bắt buộc | J33: P0 xong | K33: Đã xong | L33: 1 | M33: =H33*(1-L33) | O33: 03/09 XONG: domains/iam + migration 0004 (staff_users, roles, permissions, role_permissions, staff_roles). Seed 12 vai trò đúng ma trận phân định §2.3, chạy lại không nhân đôi.
A34: P1-02 | B34: P1 - IAM & Console khung | C34: Backend | D34: Đăng nhập nội bộ: email + mật khẩu + TOTP 2FA | E34: Bắt buộc 2FA, phiên 8 giờ, khoá sau 5 lần sai | F34: BE | H34: 4 | I34: P0-Bắt buộc | J34: domains/iam | K34: Đã xong | L34: 1 | M34: =H34*(1-L34) | O34: 03/09 XONG: email + mật khẩu + TOTP bắt buộc, phiên 8 giờ, khoá sau 5 lần sai (15 phút), admin gỡ khoá sớm được. Xoay vòng refresh token. Ghim bcrypt==4.2.1 vì passlib vỡ với bcrypt 5.
A35: P1-03 | B35: P1 - IAM & Console khung | C35: Backend | D35: Middleware kiểm permission dạng domain:action:scope | E35: Thiếu quyền trả 403 kèm mã quyền còn thiếu | F35: BE | H35: 2 | I35: P0-Bắt buộc | J35: domains/iam | K35: Đã xong | L35: 1 | M35: =H35*(1-L35) | O35: 03/09 XONG: require_permission('domain:action:scope') trả 403 kèm đúng mã quyền còn thiếu.
A36: P1-04 | B36: P1 - IAM & Console khung | C36: Backend | D36: API /ops/staff: CRUD nhân sự, gán vai trò, vô hiệu hoá | E36: Vô hiệu hoá không xoá (giữ audit trail) | F36: BE | H36: 3 | I36: P0-Bắt buộc | J36: Middleware permission | K36: Đã xong | L36: 1 | M36: =H36*(1-L36) | O36: 03/09 XONG: /ops/staff CRUD + gán vai trò + vô hiệu hoá (không xoá) + gỡ khoá. Bí mật TOTP chỉ trả về một lần lúc tạo.
A37: P1-05 | B37: P1 - IAM & Console khung | C37: Backend | D37: API đọc audit log có lọc/tra cứu | E37: Lọc theo người, thời gian, đối tượng | F37: BE | H37: 2 | I37: P1-Cao | J37: Bảng audit_logs | K37: Đã xong | L37: 1 | M37: =H37*(1-L37) | O37: 03/09 XONG: GET /ops/audit-logs lọc theo người/nhân sự/đối tượng/thời gian, phân trang con trỏ.
A38: P1-06 | B38: P1 - IAM & Console khung | C38: Backend | D38: Che PII mặc định + endpoint xem đầy đủ bắt buộc nhập lý do | E38: Mỗi lần xem CCCD/SĐT đầy đủ đều ghi log kèm lý do | F38: BE | H38: 3 | I38: P0-Bắt buộc | J38: Middleware permission | K38: Đã xong | L38: 1 | M38: =H38*(1-L38) | O38: 03/09 XONG: core/pii che SĐT/CCCD/email/tên; GET /ops/users/{id} trả bản đã che; POST /ops/users/{id}/reveal-pii cần quyền pii:full:read + lý do ≥10 ký tự, ghi vào audit_logs.reason.
A39: P1-07 | B39: P1 - IAM & Console khung | C39: Backend | D39: Khung maker-checker (approval_requests) cho thao tác chạm tiền | E39: Người tạo ≠ người duyệt; quá hạn tự huỷ | F39: BE | H39: 5 | I39: P0-Bắt buộc | J39: Middleware permission | K39: Đã xong | L39: 1 | M39: =H39*(1-L39) | O39: 03/09 XONG: approval_requests + migration 0005, 5 loại đề nghị. Người tạo không tự duyệt (kể cả super_admin), quá hạn 72h tự đóng bằng job Celery mỗi 30 phút.
A40: P1-08 | B40: P1 - IAM & Console khung | C40: Backend | D40: Tách router theo audience: rider/driver/ops/partner/public | E40: Router cũ vẫn chạy (deprecated), router mới đủ 5 nhóm | F40: BE | H40: 4 | I40: P0-Bắt buộc | J40: P0 xong | K40: Đang làm | L40: 0.4 | M40: =H40*(1-L40) | O40: 03/09: bề mặt /ops đã tách thật (iam, users, approvals, fleet/drivers/trips). Còn: /rider, /driver, /partner, /public vẫn dùng đường dẫn cũ.
A41: P1-09 | B41: P1 - IAM & Console khung | C41: Backend | D41: API /ops/fleet + WS ops.fleet_update (gom 3s/lần) | E41: Console thấy toàn bộ tài xế online và chuyến đang chạy | F41: BE | H41: 4 | I41: P0-Bắt buộc | J41: Tách router | K41: Đang làm | L41: 0.7 | M41: =H41*(1-L41) | O41: 03/09: GET /ops/fleet trả ảnh chụp toàn đội (online, đang chạy chuyến), không kèm PII. Còn: WS ops.fleet_update gom 3s/lần — chờ WS gateway đa topic ở P2.
...

Sheet Lists
A1: Trạng thái | B1: Ưu tiên | C1: Vai trò | D1: Giai đoạn
A2: Chưa bắt đầu | B2: P0-Bắt buộc | C2: TL | D2: P0 - Dọn nền
A3: Đang làm | B3: P1-Cao | C3: BE | D3: P1 - IAM & Console khung
A4: Đã xong | B4: P2-Trung bình | C4: MOB | D4: P2 - Chat & Support
A5: Bị chặn | B5: P3-Thấp | C5: FE | D5: P3 - Driver App
D6: P4 - Rider App
D7: P5 - Ledger & Finance
D8: P6 - Partner & Website
D9: P7 - Hardening

Sheet Đội ngũ
A1: ĐỘI NGŨ & NĂNG LỰC
A2: Cột G tự cộng từ Backlog theo vai trò. Cột H cho thấy ai là điểm nghẽn của dự án.
A4: Mã | B4: Vai trò | C4: Phạm vi công việc | D4: Ngày hiệu quả / sprint | E4: Hệ số sẵn sàng | F4: Năng lực thực / sprint | G4: Ngày công còn lại được giao | H4: Số sprint để làm hết | I4: Ghi chú
A5: TL | B5: Tech Lead / Full-stack | C5: Kiến trúc, backend lõi, DevOps, review code, tài liệu | D5: 8 | E5: 0.7 | F5: =D5*E5 | G5: =SUMIFS(Backlog!$M$5:$M$135,Backlog!$F$5:$F$135,$A5) | H5: =IFERROR(ROUND(G5/F5,1),0) | I5: Kiêm DevOps nên chỉ ~70% thời gian cho task trong bảng
A6: BE | B6: Backend Engineer (Python) | C6: FastAPI, domain services, migration, tích hợp bên thứ 3 | D6: 8 | E6: 0.9 | F6: =D6*E6 | G6: =SUMIFS(Backlog!$M$5:$M$135,Backlog!$F$5:$F$135,$A6) | H6: =IFERROR(ROUND(G6/F6,1),0)
A7: MOB | B7: Mobile Engineer (RN/Expo) | C7: App tài xế + app khách | D7: 8 | E7: 0.9 | F7: =D7*E7 | G7: =SUMIFS(Backlog!$M$5:$M$135,Backlog!$F$5:$F$135,$A7) | H7: =IFERROR(ROUND(G7/F7,1),0) | I7: ĐIỂM NGHẼN: 1 người gánh cả 2 app — xem sheet Rủi ro
A8: FE | B8: Frontend Engineer + QA | C8: Console, Partner Portal, Website, kiểm thử | D8: 8 | E8: 0.9 | F8: =D8*E8 | G8: =SUMIFS(Backlog!$M$5:$M$135,Backlog!$F$5:$F$135,$A8) | H8: =IFERROR(ROUND(G8/F8,1),0) | I8: Kiêm QA nên tải thực tế cao
B9: TỔNG | F9: =SUM(F5:F8) | G9: =SUM(G5:G8)
A11: CÁCH ĐỌC
A12: • Cột H tô đỏ khi vượt 12 sprint (≈6 tháng) — vai trò đó một mình đã kéo dài dự án quá nửa năm.
A13: • Ở trạng thái hiện tại, BE là vai trò nặng nhất (≈24 sprint), không phải MOB. Đây là đường găng thật — xem Rủi ro R1.
A14: • Cách cân tải rẻ nhất: Tech Lead nhận bớt ~40% khối lượng backend (đổi cột Vai trò của các task backend sang TL) và tăng hệ số sẵn sàng của TL.
A15: • Hệ số sẵn sàng: TL để 70% vì kiêm DevOps và review; các vai trò khác 90% (10% cho họp, hỗ trợ, sự cố).
A16: • Cột G chỉ tính phần CÒN LẠI (đã trừ % hoàn thành), nên sẽ giảm dần khi đội cập nhật Backlog.

Sheet Sprint
A1: KẾ HOẠCH SPRINT — 2 tuần/sprint
A2: Kế hoạch chỉ dẫn, không cứng nhắc. Điều chỉnh sau mỗi buổi họp rút kinh nghiệm cuối sprint.
A4: Sprint | B4: Tuần | C4: Giai đoạn chính | D4: Mục tiêu sprint (kết quả nhìn thấy được) | E4: Cột mốc
A5: S1 | B5: 1-2 | C5: P0 | D5: Monorepo dựng xong, CI xanh, xoá backend cũ, sinh api-client tự động
A6: S2 | B6: 3-4 | C6: P0 | D6: Staging chạy, secret tách khỏi repo, backup PITR, rate limit + idempotency trên Redis | E6: MỐC: có môi trường staging
A7: S3 | B7: 5-6 | C7: P0 → P1 | D7: Xoay vòng refresh token, audit log, khởi động domains/iam
A8: S4 | B8: 7-8 | C8: P1 | D8: Đăng nhập nội bộ 2FA, permission, khung maker-checker, Console scaffold
A9: S5 | B9: 9-10 | C9: P1 | D9: Console: IAM + Driver Ops duyệt hồ sơ | E9: MỐC: duyệt hồ sơ tài xế không cần vào DB
A10: S6 | B10: 11-12 | C10: P1 | D10: Console: Live Ops map + danh sách chuyến + tua lộ trình | E10: MỐC: Console dùng được cho vận hành
A11: S7 | B11: 13-14 | C11: P2 | D11: Data model chat, chat service, WS gateway đa topic
A12: S8 | B12: 15-16 | C12: P2 | D12: domains/support, SLA, phân công, push FCM
A13: S9 | B13: 17-18 | C13: P2 | D13: Console Support Desk + chat 3 bên + realtime-client | E13: MỐC: CSKH chat được với khách và tài xế
A14: S10 | B14: 19-20 | C14: P3 | D14: Expo scaffold + auth + spike GPS nền (ưu tiên số 1) | E14: QUYẾT ĐỊNH: Expo managed hay development build
A15: S11 | B15: 21-22 | C15: P3 | D15: Ca làm, QR động, nhận offer, điều hướng
A16: S12 | B16: 23-24 | C16: P3 | D16: GPS nền hoàn chỉnh, hàng đợi offline, tối ưu pin
A17: S13 | B17: 25-26 | C17: P3 | D17: Ví, ký quỹ, selfie, chat, phát hành nội bộ | E17: MỐC: 50 tài xế tiên phong chạy thật
A18: S14 | B18: 27-28 | C18: P4 | D18: Rider scaffold, đặt xe, ước giá, theo dõi bản đồ
A19: S15 | B19: 29-30 | C19: P4 | D19: QR, thanh toán, chia sẻ hành trình, chat
A20: S16 | B20: 31-32 | C20: P4 → P5 | D20: Hoàn thiện app khách; khởi động thiết kế sổ kép | E20: MỐC: khách dùng app thật
A21: S17 | B21: 33-34 | C21: P5 | D21: Sổ kép: migration + chuyển settlement
A22: S18 | B22: 35-36 | C22: P5 | D22: Payouts, invoices, payment state machine, VNPay thật
A23: S19 | B23: 37-38 | C23: P5 | D23: Console Finance + báo cáo unit economics | E23: MỐC: sổ sách kiểm toán được
A24: S20 | B24: 39-40 | C24: P6 | D24: Partner Portal + API /partner/*
A25: S21 | B25: 41-42 | C25: P6 | D25: CMS + website + API public | E25: MỐC: goan.vn lên sóng
A26: S22 | B26: 43-44 | C26: P7 | D26: Load test, tối ưu, pentest
A27: S23 | B27: 45-46 | C27: P7 | D27: Runbook, tuân thủ NĐ13, nộp store | E27: MỐC: sẵn sàng mở thành phố thứ 2
A30: LƯU Ý VỀ LỊCH NÀY
A31: • 23 sprint ≈ 46 tuần ≈ 11 tháng. Lịch này giả định các giai đoạn chạy tuần tự cho dễ theo dõi.
A32: • Nếu để 3 luồng (backend / mobile / frontend) chạy song song đúng cách, đường găng rút còn ~17-18 sprint (≈8 tháng) — giới hạn bởi khối lượng backend.
A33: • Hai quyết định rút ngắn lịch nhiều nhất: Tech Lead gánh bớt backend, và tuyển thêm 1 mobile trước S10.
A34: • Chat/Support (S7-S9) đặt trước app là có chủ ý: web MVP còn dùng tạm được cho khách, nhưng không có kênh hỗ trợ thì mọi sự cố phải xử lý qua điện thoại cá nhân.
A35: • P6 (Partner Portal + Website) là phần dễ thuê ngoài nhất nếu muốn rút ngắn lịch.
A36: • Quyết định về nhánh tiền mặt phải chốt TRƯỚC S17, nếu không sẽ phải làm lại tầng sổ kép.

Sheet Rủi ro
A1: SỔ RỦI RO
A2: Rà soát lại vào cuối mỗi sprint. Rủi ro R1 và R3 cần quyết định của ban lãnh đạo, không phải của đội kỹ thuật.
A4: Mã | B4: Rủi ro | C4: Khả năng xảy ra | D4: Mức ảnh hưởng | E4: Hệ quả nếu xảy ra | F4: Cách giảm thiểu | G4: Người chịu trách nhiệm
A5: R1 | B5: Tải công việc lệch nặng về Backend — 1 người gánh ~174 ngày công | C5: Chắc chắn | D5: Nghiêm trọng | E5: Theo sheet Đội ngũ: BE cần ~24 sprint (≈11 tháng) một mình, trong khi MOB ~14 và FE ~16. Backend là đường găng thật của dự án, không phải mobile | F5: Ba lựa chọn: (a) Tech Lead nhận ~40% khối lượng backend, đưa BE về ~17 sprint; (b) tuyển thêm 1 backend từ P2; (c) thuê ngoài P6. Xem lại con số này sau mỗi sprint | G5: TL
A6: R1b | B6: 1 mobile engineer gánh cả app tài xế và app khách | C6: Rất cao | D6: Nghiêm trọng | E6: P3 + P4 khoảng 104 ngày công dồn vào 1 người ≈ 14 sprint liên tục, không có ai thay khi nghỉ ốm hoặc nghỉ việc | F6: Tuyển thêm 1 mobile trước S10, hoặc chấp nhận app khách lùi 3-4 tháng và dùng web MVP thay thế trong thời gian đó | G6: TL
A7: R2 | B7: GPS nền app tài xế bị hệ điều hành giết | C7: Cao | D7: Nghiêm trọng | E7: Chuyến mất điểm GPS → sai cước, sai đối soát chạy vòng, tài xế khiếu nại | F7: Làm spike kỹ thuật 3 ngày ngay đầu P3; nếu Expo managed không đạt thì chuyển development build | G7: MOB
A8: R3 | B8: Chưa quyết định có làm nhánh tiền mặt hay không | C8: Cao | D8: Nghiêm trọng | E8: Nếu quyết muộn sau khi đã làm sổ kép thì phải sửa lại toàn bộ tầng ledger | F8: Chốt trước khi bắt đầu P5. Thị trường lái hộ VN tiền mặt còn lớn nên khả năng cao là phải làm | G8: TL
A9: R4 | B9: Ledger chưa phải double-entry | C9: Chắc chắn | D9: Nghiêm trọng | E9: Không audit được dòng tiền khi gọi vốn Series A; đối soát chỉ phát hiện lệch tổng, không truy được nguyên nhân | F9: P5 là bắt buộc, không được cắt. Trong lúc chờ, bật cảnh báo khi job đối soát báo balanced = false | G9: BE
A10: R5 | B10: Đội 4 người cho 5 sản phẩm | C10: Chắc chắn | D10: Trung bình | E10: Tổng khối lượng vượt xa năng lực đội trong 6 tháng | F10: Bám đúng thứ tự phase, không làm song song. Partner Portal và Website (P6) có thể thuê ngoài | G10: TL
A11: R6 | B11: Phụ thuộc bên thứ 3 chưa ký hợp đồng (eKYC, VNPay, hoá đơn điện tử, bản đồ) | C11: Trung bình | D11: Nghiêm trọng | E11: Sandbox và hợp đồng thường mất 4-8 tuần, có thể chặn P3 và P5 | F11: Khởi động đàm phán ngay từ P0, song song với việc code | G11: TL
A12: R7 | B12: CSKH quá tải khi mở rộng | C12: Trung bình | D12: Trung bình | E12: SLA phản hồi đầu vượt ngưỡng, khách bỏ đi | F12: Bot trả lời câu hỏi thường gặp + canned response ngay trong P2; theo dõi bảng SLA hàng tuần | G12: FE
A13: R8 | B13: Không có môi trường staging trong giai đoạn đầu | C13: Cao | D13: Trung bình | E13: Test trên production hoặc không test được tích hợp | F13: Đưa dựng staging lên đầu P0, không lùi | G13: TL

Sheet Nhật ký
A1: NHẬT KÝ TRIỂN KHAI
A2: Chỉ ghi việc đã chạy và đã kiểm chứng được, không ghi dự định. Nhánh: chore/p0-foundation
A4: Ngày | B4: Commit | C4: Hạng mục | D4: Đã làm gì | E4: Bằng chứng kiểm chứng
A5: 03/09/2026 | B5: cc30b41 | C5: Cấu trúc | D5: Dựng monorepo: goan-backend-spec → services/api, goan-backend → services/_deprecated-api-v0 (kèm DEPRECATED.md), goan-customer-app → apps/customer-web, tài liệu → docs/. Thêm pnpm workspace, turbo, .editorconfig, README | E5: 203 file thay đổi; 51/51 test vẫn xanh sau khi đổi đường dẫn
A6: 03/09/2026 | B6: cc30b41 | C6: Contract API | D6: scripts/export_openapi.py xuất OpenAPI; dựng packages/api-client (openapi-typescript + openapi-fetch) làm nguồn contract duy nhất cho mọi frontend | E6: 33 đường dẫn, 54 schema; CI có job so bản sinh mới với openapi.json đã commit
A7: 03/09/2026 | B7: cc30b41 | C7: Chất lượng | D7: Cấu hình ruff (E,F,I,UP,B,C4,SIM,ASYNC) + mypy + Makefile; sửa 92 lỗi lint; ruff format toàn bộ services/api | E7: ruff check sạch, ruff format --check sạch trên 87 file
A8: 03/09/2026 | B8: cc30b41 | C8: Bảo mật | D8: Tách /health (liveness, không chạm DB) và /ready (readiness, trả 503). Rate limit đổi sang ZSET cửa sổ trượt + hạn mức riêng cho OTP và tạo chuyến. Access token 60 → 15 phút | E8: Đọc lại mã: cửa sổ cố định cũ cho gửi gấp đôi hạn mức OTP quanh ranh giới phút
A9: 03/09/2026 | B9: ea79c35 | C9: Kiểu dữ liệu | D9: mypy sạch toàn bộ. BUG THẬT #1: complete_trip chỉ kiểm dropoff_lat mà bỏ sót dropoff_lng → haversine_m nhận None | E9: mypy: Argument 4 to haversine_m has incompatible type float | None
A10: 03/09/2026 | B10: ea79c35 | C10: Kiểu dữ liệu | D10: BUG THẬT #2: ensure_utc trả datetime|None nên mọi phép trừ thời gian ở trips/fraud không an toàn kiểu → thêm overload (datetime vào thì datetime ra) | E10: mypy: No overload variant of __sub__ of datetime matches argument type None (2 chỗ)
A11: 03/09/2026 | B11: ea79c35 | C11: Kiểu dữ liệu | D11: BUG THẬT #3: notify_users nhận list bất biến nên caller truyền list[UUID] không khớp list[UUID|str] → đổi sang Sequence | E11: mypy: Argument 1 to notify_users has incompatible type list[UUID]
A12: 03/09/2026 | B12: ea79c35 | C12: CI | D12: Bỏ toàn bộ continue-on-error: mypy, pnpm install --frozen-lockfile, sinh api-client, typecheck và build đều chặn merge thật | E12: pnpm install xanh (244 gói), pnpm build xanh, @goan/api-client typecheck sạch
A13: 03/09/2026 | B13: 399d8ab | C13: Bảo mật | D13: domains/audit: bảng audit_logs + middleware ghi mọi POST/PUT/PATCH/DELETE, che đệ quy 17 trường nhạy cảm, suy ra resource_type/resource_id từ đường dẫn | E13: 19 test QA-AUD, gồm cả test payload lồng 50 tầng không làm treo
A14: 03/09/2026 | B14: 399d8ab | C14: Bảo mật | D14: Xoay vòng refresh token theo OAuth 2.0 BCP §4.13: dùng lại token đã tiêu thì thu hồi cả họ token của thiết bị đó. Thêm POST /auth/logout | E14: 9 test QA-AUTH, gồm kịch bản token bị đánh cắp và kịch bản không đá người dùng cũ ra khi deploy
A15: 03/09/2026 | B15: 399d8ab | C15: Tiền | D15: core/idempotency: middleware chung cho 5 nhóm endpoint chạm tiền. Gửi trùng phát lại response cũ, bản gốc đang chạy trả 409, chỉ cache kết quả thành công | E15: 16 test QA-IDM chạy qua đúng chuỗi middleware thật
... A19: 03/09/2026 | B19: a1813a1 | C19: Bàn giao | D19: Soạn MERGE_REQUEST.md: ánh xạ PRD, bảng 'test này đỏ khi nào', thay đổi phá vỡ tương thích, rủi ro và cách quay lui | E19: Nhánh chore/p0-foundation, 5 commit. CHƯA push được: môi trường cầu nối không có thông tin đăng nhập GitHub
A22: ĐÁNH GIÁ BAN ĐẦU ĐÃ ĐƯỢC SỬA LẠI
A23: Ghi lại để lần sau không lặp lại, và để ai đọc bảng này biết con số nào đã thay đổi vì sao.
A25: Chủ đề | B25: Đã nói ban đầu | C25: Thực tế | D25: Đã xử lý thế nào
A26: Rate limit | B26: Đánh giá 03/09 sáng: 'RateLimitMiddleware là in-process, sai khi scale ngang' | C26: SAI. Đọc kỹ mã thì middleware vốn đã dùng Redis. Vấn đề thật nhỏ hơn nhưng vẫn đáng sửa: cửa sổ cố định theo phút cho phép gửi gấp đôi hạn mức quanh ranh giới phút — với endpoint gửi OTP thì mỗi tin là chi phí SMS thật | D26: Đã sửa cả mã lẫn dòng task tương ứng trong Backlog
A27: Đường găng dự án | B27: Giả định ban đầu: mobile là điểm nghẽn | C27: Số liệu nói khác: Backend cần ~24 sprint một mình, Mobile ~14, Frontend ~16, Tech Lead chỉ ~9. Backend mới là đường găng | D27: Đã đổi rủi ro R1 và thêm R1b; xem sheet Rủi ro
A28: Môi trường chạy test | B28: Dự kiến chạy test bằng .venv sẵn có trong repo | C28: .venv trong repo build cho macOS nên không dùng được từ môi trường Linux của cầu nối; ngoài ra máy chỉ có Python 3.10 trong khi dự án yêu cầu 3.11 | D28: Đã tạo venv riêng ngoài repo để chạy test; giữ timezone.utc thay vì datetime.UTC (tắt luật UP017) để mã còn chạy được trên 3.10
